{
 "cells": [
  {
   "cell_type": "code",
   "execution_count": 251,
   "metadata": {},
   "outputs": [
    {
     "name": "stdout",
     "output_type": "stream",
     "text": [
      "Collecting fit2gpx\n",
      "  Using cached fit2gpx-0.0.6.tar.gz (8.8 kB)\n",
      "  Preparing metadata (setup.py) ... \u001b[?25ldone\n",
      "\u001b[?25hRequirement already satisfied: pandas in /Users/wjones/opt/anaconda3/envs/dsa/lib/python3.9/site-packages (from fit2gpx) (1.5.2)\n",
      "Requirement already satisfied: gpxpy in /Users/wjones/opt/anaconda3/envs/dsa/lib/python3.9/site-packages (from fit2gpx) (1.5.0)\n",
      "Collecting fitdecode\n",
      "  Using cached fitdecode-0.10.0-py3-none-any.whl (90 kB)\n",
      "Requirement already satisfied: python-dateutil>=2.8.1 in /Users/wjones/opt/anaconda3/envs/dsa/lib/python3.9/site-packages (from pandas->fit2gpx) (2.8.2)\n",
      "Requirement already satisfied: pytz>=2020.1 in /Users/wjones/opt/anaconda3/envs/dsa/lib/python3.9/site-packages (from pandas->fit2gpx) (2022.1)\n",
      "Requirement already satisfied: numpy>=1.20.3 in /Users/wjones/opt/anaconda3/envs/dsa/lib/python3.9/site-packages (from pandas->fit2gpx) (1.23.4)\n",
      "Requirement already satisfied: six>=1.5 in /Users/wjones/opt/anaconda3/envs/dsa/lib/python3.9/site-packages (from python-dateutil>=2.8.1->pandas->fit2gpx) (1.16.0)\n",
      "Building wheels for collected packages: fit2gpx\n",
      "  Building wheel for fit2gpx (setup.py) ... \u001b[?25ldone\n",
      "\u001b[?25h  Created wheel for fit2gpx: filename=fit2gpx-0.0.6-py3-none-any.whl size=8194 sha256=8e328d85f819b8100d1510b484851ee96025f27f75e523cfdd150be127c96aa7\n",
      "  Stored in directory: /Users/wjones/Library/Caches/pip/wheels/fb/0f/68/223e3b1e6827c306b647aa5c72454a2388f296cff8c553d067\n",
      "Successfully built fit2gpx\n",
      "Installing collected packages: fitdecode, fit2gpx\n",
      "Successfully installed fit2gpx-0.0.6 fitdecode-0.10.0\n"
     ]
    }
   ],
   "source": [
    "import scipy as sc\n",
    "import numpy as np\n",
    "#!pip install gpxpy\n",
    "import gpxpy\n",
    "from geopy import distance\n",
    "import json\n",
    "import pandas as pd\n",
    "import math\n",
    "!pip install fit2gpx\n",
    "from fit2gpx import Converter"
   ]
  },
  {
   "attachments": {},
   "cell_type": "markdown",
   "metadata": {},
   "source": [
    "# Putting it all together:"
   ]
  },
  {
   "attachments": {},
   "cell_type": "markdown",
   "metadata": {},
   "source": [
    "1. read gpx file(s) into an array with elevations and coordinates\n",
    "2. read segement data into array with elevations and coordinates\n",
    "3. get total distance and total elevation difference from segment\n",
    "4. sweep through gpx arrays to find sections that roughly fit the segment\n",
    "5. calculate elapsed times for those sections\n",
    "6. use DTW to see if segments are actually similar\n",
    "    - if they are, compare times.\n",
    "\n",
    "- Thought - skip the prelim data sweep and just use DTW"
   ]
  },
  {
   "cell_type": "code",
   "execution_count": 215,
   "metadata": {},
   "outputs": [],
   "source": [
    "def dtw(s, t, window):\n",
    "    n, m = len(s), len(t)\n",
    "    w = np.max([window, abs(n-m)])\n",
    "    dtw_matrix = np.zeros((n+1, m+1))\n",
    "    \n",
    "    for i in range(n+1):\n",
    "        for j in range(m+1):\n",
    "            dtw_matrix[i, j] = np.inf\n",
    "    dtw_matrix[0, 0] = 0\n",
    "    \n",
    "    for i in range(1, n+1):\n",
    "        for j in range(np.max([1, i-w]), np.min([m, i+w])+1):\n",
    "            dtw_matrix[i, j] = 0\n",
    "    \n",
    "    for i in range(1, n+1):\n",
    "        for j in range(np.max([1, i-w]), np.min([m, i+w])+1):\n",
    "            cost = abs(s[i-1] - t[j-1])\n",
    "            #print(cost)\n",
    "            # take last min from a square box\n",
    "            last_min = np.min([dtw_matrix[i-1, j], dtw_matrix[i, j-1], dtw_matrix[i-1, j-1]])\n",
    "            dtw_matrix[i, j] = cost + last_min\n",
    "    return dtw_matrix"
   ]
  },
  {
   "cell_type": "code",
   "execution_count": 216,
   "metadata": {},
   "outputs": [],
   "source": [
    "def dtw(s, t):\n",
    "    n, m = len(s), len(t)\n",
    "    dtw_matrix = np.zeros((n+1, m+1))\n",
    "    for i in range(n+1):\n",
    "        for j in range(m+1):\n",
    "            dtw_matrix[i, j] = np.inf\n",
    "    dtw_matrix[0, 0] = 0\n",
    "    \n",
    "    for i in range(1, n+1):\n",
    "        for j in range(1, m+1):\n",
    "            cost = abs(s[i-1] - t[j-1])\n",
    "            # take last min from a square box\n",
    "            last_min = np.min([dtw_matrix[i-1, j], dtw_matrix[i, j-1], dtw_matrix[i-1, j-1]])\n",
    "            dtw_matrix[i, j] = cost + last_min\n",
    "    return dtw_matrix"
   ]
  },
  {
   "cell_type": "code",
   "execution_count": 217,
   "metadata": {},
   "outputs": [],
   "source": [
    "from geopy import distance\n",
    "import math\n",
    "# method to calculate distances between point\n",
    "def distanceBetweenPoints(p1, p2):\n",
    "    flat_distance = distance.distance(p1[:2], p2[:2]).m\n",
    "    # print(flat_distance)\n",
    "    euclidian_distance = math.sqrt(flat_distance**2 + (p2[2] - p1[2])**2)\n",
    "    return euclidian_distance"
   ]
  },
  {
   "cell_type": "code",
   "execution_count": 218,
   "metadata": {},
   "outputs": [],
   "source": [
    "from geopy import Point\n",
    "import math\n",
    "# method to make GPX file into array of elevations, times, distances\n",
    "def file_to_elevation_arr(fileName):\n",
    "        gpx_file = open(fileName, 'r')\n",
    "        gpx = gpxpy.parse(gpx_file)\n",
    "        elevevation_time_and_distance = []\n",
    "        pointOne = None\n",
    "        for track in gpx.tracks:\n",
    "            for segment in track.segments:\n",
    "                for point in segment.points:\n",
    "                    pointTwo = point\n",
    "                    distance = 0\n",
    "                    if pointOne:\n",
    "                        p1 = Point([pointOne.latitude, pointOne.longitude, pointOne.elevation])\n",
    "                        p2 = Point([pointTwo.latitude, pointTwo.longitude, pointTwo.elevation])\n",
    "                        distance = distanceBetweenPoints(p1, p2)\n",
    "                    pointOne = point\n",
    "                    #print('Point at ({0},{1}) -> {2}'.format(point.latitude, point.longitude, point.elevation))\n",
    "                    elevevation_time_and_distance.append((point.elevation,point.time, distance))\n",
    "        return elevevation_time_and_distance"
   ]
  },
  {
   "cell_type": "code",
   "execution_count": 219,
   "metadata": {},
   "outputs": [],
   "source": [
    "fileOne = \"data/Walt's Strava/activities/5378707142.gpx\"\n",
    "fileTwo  = \"data/Walt's Strava/activities/4812864781.gpx\""
   ]
  },
  {
   "cell_type": "code",
   "execution_count": 220,
   "metadata": {},
   "outputs": [],
   "source": [
    "arrOne = file_to_elevation_arr(fileOne)\n",
    "#print(arrOne)\n",
    "arrTwo = file_to_elevation_arr(fileTwo)"
   ]
  },
  {
   "cell_type": "code",
   "execution_count": null,
   "metadata": {},
   "outputs": [],
   "source": []
  },
  {
   "cell_type": "code",
   "execution_count": 221,
   "metadata": {},
   "outputs": [],
   "source": [
    "segment = \"data/Elevation JSON/segment_location_data_elevation_0.json\""
   ]
  },
  {
   "cell_type": "code",
   "execution_count": 222,
   "metadata": {},
   "outputs": [
    {
     "data": {
      "text/html": [
       "<div>\n",
       "<style scoped>\n",
       "    .dataframe tbody tr th:only-of-type {\n",
       "        vertical-align: middle;\n",
       "    }\n",
       "\n",
       "    .dataframe tbody tr th {\n",
       "        vertical-align: top;\n",
       "    }\n",
       "\n",
       "    .dataframe thead th {\n",
       "        text-align: right;\n",
       "    }\n",
       "</style>\n",
       "<table border=\"1\" class=\"dataframe\">\n",
       "  <thead>\n",
       "    <tr style=\"text-align: right;\">\n",
       "      <th></th>\n",
       "      <th>lat</th>\n",
       "      <th>lon</th>\n",
       "      <th>elev_meters</th>\n",
       "      <th>distance</th>\n",
       "    </tr>\n",
       "  </thead>\n",
       "  <tbody>\n",
       "    <tr>\n",
       "      <th>0</th>\n",
       "      <td>34.09464</td>\n",
       "      <td>-117.71377</td>\n",
       "      <td>355.14</td>\n",
       "      <td>0.000000</td>\n",
       "    </tr>\n",
       "    <tr>\n",
       "      <th>1</th>\n",
       "      <td>34.09467</td>\n",
       "      <td>-117.71362</td>\n",
       "      <td>355.22</td>\n",
       "      <td>14.236931</td>\n",
       "    </tr>\n",
       "    <tr>\n",
       "      <th>2</th>\n",
       "      <td>34.09467</td>\n",
       "      <td>-117.71327</td>\n",
       "      <td>355.12</td>\n",
       "      <td>32.298915</td>\n",
       "    </tr>\n",
       "    <tr>\n",
       "      <th>3</th>\n",
       "      <td>34.09476</td>\n",
       "      <td>-117.71181</td>\n",
       "      <td>356.33</td>\n",
       "      <td>135.106672</td>\n",
       "    </tr>\n",
       "    <tr>\n",
       "      <th>4</th>\n",
       "      <td>34.09474</td>\n",
       "      <td>-117.71131</td>\n",
       "      <td>356.34</td>\n",
       "      <td>46.194346</td>\n",
       "    </tr>\n",
       "  </tbody>\n",
       "</table>\n",
       "</div>"
      ],
      "text/plain": [
       "        lat        lon  elev_meters    distance\n",
       "0  34.09464 -117.71377       355.14    0.000000\n",
       "1  34.09467 -117.71362       355.22   14.236931\n",
       "2  34.09467 -117.71327       355.12   32.298915\n",
       "3  34.09476 -117.71181       356.33  135.106672\n",
       "4  34.09474 -117.71131       356.34   46.194346"
      ]
     },
     "execution_count": 222,
     "metadata": {},
     "output_type": "execute_result"
    }
   ],
   "source": [
    "df = pd.read_json(segment)\n",
    "df.head()\n"
   ]
  },
  {
   "cell_type": "code",
   "execution_count": 223,
   "metadata": {},
   "outputs": [],
   "source": [
    "def dataframe_segment_to_list(df):\n",
    "    sg =[]\n",
    "    # Iterate over each row\n",
    "    for index, rows in df.iterrows():\n",
    "        # Create list for the current row\n",
    "        my_list =[rows[2], rows[3]]\n",
    "        #print(my_list)\n",
    "        \n",
    "        # append the list to the final list\n",
    "        sg.append(my_list)\n",
    "    return sg\n",
    "  "
   ]
  },
  {
   "cell_type": "code",
   "execution_count": 224,
   "metadata": {},
   "outputs": [],
   "source": [
    "#print(segment_data)\n",
    "def total_segment_elevation(segment_data):\n",
    "    total_elev = segment_data[len(segment_data)-1][0] - segment_data[0][0]\n",
    "    return total_elev\n",
    "\n",
    "def total_segment_distance(segment_data):\n",
    "    total_distance = 0\n",
    "    for i in segment_data:\n",
    "        total_distance += i[1].item()\n",
    "    return total_distance"
   ]
  },
  {
   "cell_type": "code",
   "execution_count": 237,
   "metadata": {},
   "outputs": [],
   "source": [
    "def sweep_user_activity_old(user_data, segement_data, x):\n",
    "    list_of_matches = [] # list of lists\n",
    "\n",
    "    seg_distance = total_segment_distance(segement_data)\n",
    "\n",
    "    #print(seg_distance)\n",
    "    seg_elevation = total_segment_elevation(segement_data)\n",
    "    #print(seg_elevation)\n",
    "    \n",
    "    user_distance = 0\n",
    "    user_elev = user_data[0][0]\n",
    "    user_start_elev = user_data[0][0]\n",
    "    first_window = 0\n",
    "    while user_distance < seg_distance and first_window < len(user_data):\n",
    "        # until we get to the window \n",
    "        user_elev = user_data[first_window][0]-user_start_elev\n",
    "        user_distance += user_data[first_window][2]\n",
    "        first_window += 1\n",
    "    delta_distance = user_distance - user_data[0][2]\n",
    "    # now we have the window, so we need to iterate through and see if the profiles match\n",
    "    second_window = 0\n",
    "    second_distance = 0\n",
    "    user_elev_two = user_data[0][0]\n",
    "    while user_distance < user_data[-1][2] and first_window < len(user_data):\n",
    "        user_elev_two = user_data[first_window][0]\n",
    "        user_elev = user_data[second_window][0]\n",
    "        if user_elev_two - user_elev > seg_elevation-5 and  user_elev_two - user_elev < seg_elevation+5:\n",
    "            list_of_matches.append(user_data[second_window:first_window])\n",
    "            #print(first_window, second_window)\n",
    "            # add match to list\n",
    "        user_distance += user_data[first_window][2]\n",
    "        second_distance += user_data[second_window][2]\n",
    "        first_window +=1\n",
    "        second_window +=1\n",
    "    return list_of_matches\n",
    "\n",
    "\n"
   ]
  },
  {
   "cell_type": "code",
   "execution_count": 238,
   "metadata": {},
   "outputs": [],
   "source": [
    "# What does this need to do?\n",
    "# Go to segment distance, when the segment distance matches the user window, compare elevations\n",
    "def sweep_user_activity(user_data, segement_data, window):\n",
    "    list_of_matches = [] # list of lists\n",
    "    seg_distance = total_segment_distance(segement_data) # total segment distance\n",
    "    seg_elevation = total_segment_elevation(segement_data) # total segment elevation\n",
    "    \n",
    "    # go to the correct distance in user\n",
    "    user_distance = 0\n",
    "    user_elev = user_data[0][0]\n",
    "    user_start_elev = user_data[0][0]\n",
    "    first_window = 0\n",
    "    while user_distance < seg_distance and first_window < len(user_data):\n",
    "        user_elev = user_data[first_window][0]-user_start_elev\n",
    "        user_distance += user_data[first_window][2]\n",
    "        first_window+=1\n",
    "    second_window = 0 \n",
    "    second_distance = 0\n",
    "    while first_window < len(user_data)-1: \n",
    "        while user_distance-second_distance < seg_distance and first_window < len(user_data)-1:\n",
    "            user_distance += user_data[first_window][2]\n",
    "            first_window+=1\n",
    "        user_elev_two = user_data[first_window][0]\n",
    "        user_elev = user_data[second_window][0]\n",
    "        second_distance += user_data[second_window][2]\n",
    "        if user_elev_two - user_elev > seg_elevation-window and  user_elev_two - user_elev < seg_elevation+window:\n",
    "            list_of_matches.append(user_data[second_window:first_window])\n",
    "        second_window+= 1\n",
    "    return list_of_matches\n",
    "        \n"
   ]
  },
  {
   "cell_type": "code",
   "execution_count": 227,
   "metadata": {},
   "outputs": [],
   "source": [
    "# TODO: add DTW algorithm match"
   ]
  },
  {
   "cell_type": "code",
   "execution_count": 239,
   "metadata": {},
   "outputs": [],
   "source": [
    "claremont_turkey_trot = dataframe_segment_to_list(df)\n",
    "#print(claremont_turkey_trot)\n",
    "arr = sweep_user_activity(arrTwo, claremont_turkey_trot, 5)\n",
    "#print(arr)"
   ]
  },
  {
   "cell_type": "code",
   "execution_count": 229,
   "metadata": {},
   "outputs": [],
   "source": [
    "#print(arr[0])"
   ]
  },
  {
   "cell_type": "code",
   "execution_count": 230,
   "metadata": {},
   "outputs": [],
   "source": [
    "import matplotlib.pyplot as plt\n",
    "    "
   ]
  },
  {
   "cell_type": "code",
   "execution_count": 231,
   "metadata": {},
   "outputs": [],
   "source": [
    "import numpy as np\n",
    "import matplotlib.pyplot as plt\n",
    "def graphing(user, segment):\n",
    "    total_user_distance = 0\n",
    "    total_segment_distance1 = 0\n",
    "    user_start_elev = user[0][0]\n",
    "    segment_start_elev = segment[0][0]\n",
    "    user_dtw_list = []\n",
    "    segment_dtw_list = []\n",
    "    for i in range(len(user)):\n",
    "        total_user_distance += user[i][2]\n",
    "        user_dtw_list.append(user[i][0]-user_start_elev)\n",
    "        #plt.scatter(total_user_distance, user[i][0])\n",
    "        #print(arr[0][i][0])\n",
    "    for j in range (len(segment)):\n",
    "         total_segment_distance1 += segment[j][1]\n",
    "         segment_dtw_list.append(segment[j][0]-segment_start_elev)\n",
    "         #plt.scatter(total_segment_distance1, segment[j][0])\n",
    "    #plt.draw()\n",
    "    return (user_dtw_list, segment_dtw_list)"
   ]
  },
  {
   "cell_type": "code",
   "execution_count": 247,
   "metadata": {},
   "outputs": [],
   "source": [
    "l = graphing(arr[0], claremont_turkey_trot)\n",
    "def DTW_comparison(user, segment):\n",
    "    distances = []\n",
    "    user_times = []\n",
    "    d_t = []\n",
    "    for pot in range(len(user)):\n",
    "        t1 = user[pot][0][1]\n",
    "        t2 = user[pot][-1][1]\n",
    "        #print(t1)\n",
    "        user_times.append((t2-t1).total_seconds())\n",
    "        l = graphing(user[pot], segment)\n",
    "        tempDTW = dtw(l[0], l[1])\n",
    "        distances.append(tempDTW[-1][-1])\n",
    "    for d in range(len(distances)):\n",
    "        d_t.append((distances[d],user_times[d]))\n",
    "    return d_t\n",
    "    \n"
   ]
  },
  {
   "cell_type": "code",
   "execution_count": 248,
   "metadata": {},
   "outputs": [],
   "source": [
    "d = DTW_comparison(arr, claremont_turkey_trot)\n"
   ]
  },
  {
   "cell_type": "code",
   "execution_count": 249,
   "metadata": {},
   "outputs": [
    {
     "name": "stdout",
     "output_type": "stream",
     "text": [
      "[(20697.829999999834, 1682.0), (20697.829999999834, 1681.0), (20035.899999999943, 1629.0), (20035.899999999943, 1628.0), (20035.899999999943, 1627.0)]\n"
     ]
    }
   ],
   "source": [
    "print(d)    "
   ]
  },
  {
   "cell_type": "code",
   "execution_count": 272,
   "metadata": {},
   "outputs": [],
   "source": [
    "conv = Converter() \n",
    "def fit_to_gpx(fileDirectory):\n",
    "    conv.fit_to_gpx_bulk(dir_in=fileDirectory, dir_out='data/User')\n",
    "\n"
   ]
  },
  {
   "cell_type": "code",
   "execution_count": 273,
   "metadata": {},
   "outputs": [
    {
     "name": "stderr",
     "output_type": "stream",
     "text": [
      "/Users/wjones/opt/anaconda3/envs/dsa/lib/python3.9/site-packages/fitdecode/reader.py:909: UserWarning: 'field \"native_field_num\" (idx #0) not found in message \"field_description\"' (local_mesg_num: 0; chunk_offset: 194); adding dummy dev data...\n",
      "  warnings.warn(msg)\n",
      "/Users/wjones/opt/anaconda3/envs/dsa/lib/python3.9/site-packages/fitdecode/reader.py:909: UserWarning: 'field \"native_field_num\" (idx #0) not found in message \"field_description\"' (local_mesg_num: 0; chunk_offset: 236); adding dummy dev data...\n",
      "  warnings.warn(msg)\n",
      "/Users/wjones/opt/anaconda3/envs/dsa/lib/python3.9/site-packages/fitdecode/reader.py:909: UserWarning: 'field \"native_field_num\" (idx #0) not found in message \"field_description\"' (local_mesg_num: 0; chunk_offset: 287); adding dummy dev data...\n",
      "  warnings.warn(msg)\n",
      "/Users/wjones/opt/anaconda3/envs/dsa/lib/python3.9/site-packages/fitdecode/reader.py:909: UserWarning: 'field \"native_field_num\" (idx #0) not found in message \"field_description\"' (local_mesg_num: 0; chunk_offset: 307); adding dummy dev data...\n",
      "  warnings.warn(msg)\n",
      "/Users/wjones/opt/anaconda3/envs/dsa/lib/python3.9/site-packages/fitdecode/reader.py:909: UserWarning: 'field \"native_field_num\" (idx #0) not found in message \"field_description\"' (local_mesg_num: 0; chunk_offset: 327); adding dummy dev data...\n",
      "  warnings.warn(msg)\n",
      "/Users/wjones/opt/anaconda3/envs/dsa/lib/python3.9/site-packages/fitdecode/reader.py:909: UserWarning: 'field \"native_field_num\" (idx #0) not found in message \"field_description\"' (local_mesg_num: 0; chunk_offset: 347); adding dummy dev data...\n",
      "  warnings.warn(msg)\n",
      "/Users/wjones/opt/anaconda3/envs/dsa/lib/python3.9/site-packages/fitdecode/reader.py:909: UserWarning: 'field \"native_field_num\" (idx #0) not found in message \"field_description\"' (local_mesg_num: 0; chunk_offset: 367); adding dummy dev data...\n",
      "  warnings.warn(msg)\n",
      "/Users/wjones/opt/anaconda3/envs/dsa/lib/python3.9/site-packages/fitdecode/reader.py:584: UserWarning: invalid field size 1 in definition message @ 26846 for type uint32 (expected a multiple of 4)\n",
      "  warnings.warn(msg)\n",
      "/Users/wjones/opt/anaconda3/envs/dsa/lib/python3.9/site-packages/fitdecode/reader.py:584: UserWarning: invalid field size 1 in definition message @ 27418 for type uint32 (expected a multiple of 4)\n",
      "  warnings.warn(msg)\n",
      "/Users/wjones/opt/anaconda3/envs/dsa/lib/python3.9/site-packages/fitdecode/reader.py:584: UserWarning: invalid field size 1 in definition message @ 57370 for type uint32 (expected a multiple of 4)\n",
      "  warnings.warn(msg)\n",
      "/Users/wjones/opt/anaconda3/envs/dsa/lib/python3.9/site-packages/fitdecode/reader.py:584: UserWarning: invalid field size 1 in definition message @ 61592 for type uint32 (expected a multiple of 4)\n",
      "  warnings.warn(msg)\n",
      "/Users/wjones/opt/anaconda3/envs/dsa/lib/python3.9/site-packages/fitdecode/reader.py:584: UserWarning: invalid field size 1 in definition message @ 110940 for type uint32 (expected a multiple of 4)\n",
      "  warnings.warn(msg)\n",
      "/Users/wjones/opt/anaconda3/envs/dsa/lib/python3.9/site-packages/fitdecode/reader.py:909: UserWarning: 'field \"native_field_num\" (idx #0) not found in message \"field_description\"' (local_mesg_num: 0; chunk_offset: 194); adding dummy dev data...\n",
      "  warnings.warn(msg)\n",
      "/Users/wjones/opt/anaconda3/envs/dsa/lib/python3.9/site-packages/fitdecode/reader.py:909: UserWarning: 'field \"native_field_num\" (idx #0) not found in message \"field_description\"' (local_mesg_num: 0; chunk_offset: 236); adding dummy dev data...\n",
      "  warnings.warn(msg)\n",
      "/Users/wjones/opt/anaconda3/envs/dsa/lib/python3.9/site-packages/fitdecode/reader.py:909: UserWarning: 'field \"native_field_num\" (idx #0) not found in message \"field_description\"' (local_mesg_num: 0; chunk_offset: 287); adding dummy dev data...\n",
      "  warnings.warn(msg)\n",
      "/Users/wjones/opt/anaconda3/envs/dsa/lib/python3.9/site-packages/fitdecode/reader.py:909: UserWarning: 'field \"native_field_num\" (idx #0) not found in message \"field_description\"' (local_mesg_num: 0; chunk_offset: 307); adding dummy dev data...\n",
      "  warnings.warn(msg)\n",
      "/Users/wjones/opt/anaconda3/envs/dsa/lib/python3.9/site-packages/fitdecode/reader.py:909: UserWarning: 'field \"native_field_num\" (idx #0) not found in message \"field_description\"' (local_mesg_num: 0; chunk_offset: 327); adding dummy dev data...\n",
      "  warnings.warn(msg)\n",
      "/Users/wjones/opt/anaconda3/envs/dsa/lib/python3.9/site-packages/fitdecode/reader.py:909: UserWarning: 'field \"native_field_num\" (idx #0) not found in message \"field_description\"' (local_mesg_num: 0; chunk_offset: 347); adding dummy dev data...\n",
      "  warnings.warn(msg)\n",
      "/Users/wjones/opt/anaconda3/envs/dsa/lib/python3.9/site-packages/fitdecode/reader.py:909: UserWarning: 'field \"native_field_num\" (idx #0) not found in message \"field_description\"' (local_mesg_num: 0; chunk_offset: 367); adding dummy dev data...\n",
      "  warnings.warn(msg)\n",
      "/Users/wjones/opt/anaconda3/envs/dsa/lib/python3.9/site-packages/fitdecode/reader.py:584: UserWarning: invalid field size 1 in definition message @ 26406 for type uint32 (expected a multiple of 4)\n",
      "  warnings.warn(msg)\n",
      "/Users/wjones/opt/anaconda3/envs/dsa/lib/python3.9/site-packages/fitdecode/reader.py:584: UserWarning: invalid field size 1 in definition message @ 36395 for type uint32 (expected a multiple of 4)\n",
      "  warnings.warn(msg)\n",
      "/Users/wjones/opt/anaconda3/envs/dsa/lib/python3.9/site-packages/fitdecode/reader.py:584: UserWarning: invalid field size 1 in definition message @ 53516 for type uint32 (expected a multiple of 4)\n",
      "  warnings.warn(msg)\n",
      "/Users/wjones/opt/anaconda3/envs/dsa/lib/python3.9/site-packages/fitdecode/reader.py:584: UserWarning: invalid field size 1 in definition message @ 56913 for type uint32 (expected a multiple of 4)\n",
      "  warnings.warn(msg)\n",
      "/Users/wjones/opt/anaconda3/envs/dsa/lib/python3.9/site-packages/fitdecode/reader.py:909: UserWarning: 'field \"native_field_num\" (idx #0) not found in message \"field_description\"' (local_mesg_num: 0; chunk_offset: 194); adding dummy dev data...\n",
      "  warnings.warn(msg)\n",
      "/Users/wjones/opt/anaconda3/envs/dsa/lib/python3.9/site-packages/fitdecode/reader.py:909: UserWarning: 'field \"native_field_num\" (idx #0) not found in message \"field_description\"' (local_mesg_num: 0; chunk_offset: 236); adding dummy dev data...\n",
      "  warnings.warn(msg)\n",
      "/Users/wjones/opt/anaconda3/envs/dsa/lib/python3.9/site-packages/fitdecode/reader.py:909: UserWarning: 'field \"native_field_num\" (idx #0) not found in message \"field_description\"' (local_mesg_num: 0; chunk_offset: 287); adding dummy dev data...\n",
      "  warnings.warn(msg)\n",
      "/Users/wjones/opt/anaconda3/envs/dsa/lib/python3.9/site-packages/fitdecode/reader.py:909: UserWarning: 'field \"native_field_num\" (idx #0) not found in message \"field_description\"' (local_mesg_num: 0; chunk_offset: 307); adding dummy dev data...\n",
      "  warnings.warn(msg)\n",
      "/Users/wjones/opt/anaconda3/envs/dsa/lib/python3.9/site-packages/fitdecode/reader.py:909: UserWarning: 'field \"native_field_num\" (idx #0) not found in message \"field_description\"' (local_mesg_num: 0; chunk_offset: 327); adding dummy dev data...\n",
      "  warnings.warn(msg)\n",
      "/Users/wjones/opt/anaconda3/envs/dsa/lib/python3.9/site-packages/fitdecode/reader.py:909: UserWarning: 'field \"native_field_num\" (idx #0) not found in message \"field_description\"' (local_mesg_num: 0; chunk_offset: 347); adding dummy dev data...\n",
      "  warnings.warn(msg)\n",
      "/Users/wjones/opt/anaconda3/envs/dsa/lib/python3.9/site-packages/fitdecode/reader.py:909: UserWarning: 'field \"native_field_num\" (idx #0) not found in message \"field_description\"' (local_mesg_num: 0; chunk_offset: 367); adding dummy dev data...\n",
      "  warnings.warn(msg)\n",
      "/Users/wjones/opt/anaconda3/envs/dsa/lib/python3.9/site-packages/fitdecode/reader.py:584: UserWarning: invalid field size 1 in definition message @ 26000 for type uint32 (expected a multiple of 4)\n",
      "  warnings.warn(msg)\n",
      "/Users/wjones/opt/anaconda3/envs/dsa/lib/python3.9/site-packages/fitdecode/reader.py:584: UserWarning: invalid field size 1 in definition message @ 45090 for type uint32 (expected a multiple of 4)\n",
      "  warnings.warn(msg)\n",
      "/Users/wjones/opt/anaconda3/envs/dsa/lib/python3.9/site-packages/fitdecode/reader.py:584: UserWarning: invalid field size 1 in definition message @ 61927 for type uint32 (expected a multiple of 4)\n",
      "  warnings.warn(msg)\n",
      "/Users/wjones/opt/anaconda3/envs/dsa/lib/python3.9/site-packages/fitdecode/reader.py:584: UserWarning: invalid field size 1 in definition message @ 78537 for type uint32 (expected a multiple of 4)\n",
      "  warnings.warn(msg)\n",
      "/Users/wjones/opt/anaconda3/envs/dsa/lib/python3.9/site-packages/fitdecode/reader.py:584: UserWarning: invalid field size 1 in definition message @ 97802 for type uint32 (expected a multiple of 4)\n",
      "  warnings.warn(msg)\n",
      "/Users/wjones/opt/anaconda3/envs/dsa/lib/python3.9/site-packages/fitdecode/reader.py:584: UserWarning: invalid field size 1 in definition message @ 136113 for type uint32 (expected a multiple of 4)\n",
      "  warnings.warn(msg)\n",
      "/Users/wjones/opt/anaconda3/envs/dsa/lib/python3.9/site-packages/fitdecode/reader.py:909: UserWarning: 'field \"native_field_num\" (idx #0) not found in message \"field_description\"' (local_mesg_num: 0; chunk_offset: 194); adding dummy dev data...\n",
      "  warnings.warn(msg)\n",
      "/Users/wjones/opt/anaconda3/envs/dsa/lib/python3.9/site-packages/fitdecode/reader.py:909: UserWarning: 'field \"native_field_num\" (idx #0) not found in message \"field_description\"' (local_mesg_num: 0; chunk_offset: 236); adding dummy dev data...\n",
      "  warnings.warn(msg)\n",
      "/Users/wjones/opt/anaconda3/envs/dsa/lib/python3.9/site-packages/fitdecode/reader.py:909: UserWarning: 'field \"native_field_num\" (idx #0) not found in message \"field_description\"' (local_mesg_num: 0; chunk_offset: 287); adding dummy dev data...\n",
      "  warnings.warn(msg)\n",
      "/Users/wjones/opt/anaconda3/envs/dsa/lib/python3.9/site-packages/fitdecode/reader.py:909: UserWarning: 'field \"native_field_num\" (idx #0) not found in message \"field_description\"' (local_mesg_num: 0; chunk_offset: 307); adding dummy dev data...\n",
      "  warnings.warn(msg)\n",
      "/Users/wjones/opt/anaconda3/envs/dsa/lib/python3.9/site-packages/fitdecode/reader.py:909: UserWarning: 'field \"native_field_num\" (idx #0) not found in message \"field_description\"' (local_mesg_num: 0; chunk_offset: 327); adding dummy dev data...\n",
      "  warnings.warn(msg)\n",
      "/Users/wjones/opt/anaconda3/envs/dsa/lib/python3.9/site-packages/fitdecode/reader.py:909: UserWarning: 'field \"native_field_num\" (idx #0) not found in message \"field_description\"' (local_mesg_num: 0; chunk_offset: 347); adding dummy dev data...\n",
      "  warnings.warn(msg)\n",
      "/Users/wjones/opt/anaconda3/envs/dsa/lib/python3.9/site-packages/fitdecode/reader.py:909: UserWarning: 'field \"native_field_num\" (idx #0) not found in message \"field_description\"' (local_mesg_num: 0; chunk_offset: 367); adding dummy dev data...\n",
      "  warnings.warn(msg)\n",
      "/Users/wjones/opt/anaconda3/envs/dsa/lib/python3.9/site-packages/fitdecode/reader.py:584: UserWarning: invalid field size 1 in definition message @ 25393 for type uint32 (expected a multiple of 4)\n",
      "  warnings.warn(msg)\n",
      "/Users/wjones/opt/anaconda3/envs/dsa/lib/python3.9/site-packages/fitdecode/reader.py:584: UserWarning: invalid field size 1 in definition message @ 52897 for type uint32 (expected a multiple of 4)\n",
      "  warnings.warn(msg)\n",
      "/Users/wjones/opt/anaconda3/envs/dsa/lib/python3.9/site-packages/fitdecode/reader.py:909: UserWarning: 'field \"native_field_num\" (idx #0) not found in message \"field_description\"' (local_mesg_num: 0; chunk_offset: 194); adding dummy dev data...\n",
      "  warnings.warn(msg)\n",
      "/Users/wjones/opt/anaconda3/envs/dsa/lib/python3.9/site-packages/fitdecode/reader.py:909: UserWarning: 'field \"native_field_num\" (idx #0) not found in message \"field_description\"' (local_mesg_num: 0; chunk_offset: 236); adding dummy dev data...\n",
      "  warnings.warn(msg)\n",
      "/Users/wjones/opt/anaconda3/envs/dsa/lib/python3.9/site-packages/fitdecode/reader.py:909: UserWarning: 'field \"native_field_num\" (idx #0) not found in message \"field_description\"' (local_mesg_num: 0; chunk_offset: 287); adding dummy dev data...\n",
      "  warnings.warn(msg)\n",
      "/Users/wjones/opt/anaconda3/envs/dsa/lib/python3.9/site-packages/fitdecode/reader.py:909: UserWarning: 'field \"native_field_num\" (idx #0) not found in message \"field_description\"' (local_mesg_num: 0; chunk_offset: 307); adding dummy dev data...\n",
      "  warnings.warn(msg)\n",
      "/Users/wjones/opt/anaconda3/envs/dsa/lib/python3.9/site-packages/fitdecode/reader.py:909: UserWarning: 'field \"native_field_num\" (idx #0) not found in message \"field_description\"' (local_mesg_num: 0; chunk_offset: 327); adding dummy dev data...\n",
      "  warnings.warn(msg)\n",
      "/Users/wjones/opt/anaconda3/envs/dsa/lib/python3.9/site-packages/fitdecode/reader.py:909: UserWarning: 'field \"native_field_num\" (idx #0) not found in message \"field_description\"' (local_mesg_num: 0; chunk_offset: 347); adding dummy dev data...\n",
      "  warnings.warn(msg)\n",
      "/Users/wjones/opt/anaconda3/envs/dsa/lib/python3.9/site-packages/fitdecode/reader.py:909: UserWarning: 'field \"native_field_num\" (idx #0) not found in message \"field_description\"' (local_mesg_num: 0; chunk_offset: 367); adding dummy dev data...\n",
      "  warnings.warn(msg)\n",
      "/Users/wjones/opt/anaconda3/envs/dsa/lib/python3.9/site-packages/fitdecode/reader.py:909: UserWarning: 'field \"native_field_num\" (idx #0) not found in message \"field_description\"' (local_mesg_num: 0; chunk_offset: 194); adding dummy dev data...\n",
      "  warnings.warn(msg)\n",
      "/Users/wjones/opt/anaconda3/envs/dsa/lib/python3.9/site-packages/fitdecode/reader.py:909: UserWarning: 'field \"native_field_num\" (idx #0) not found in message \"field_description\"' (local_mesg_num: 0; chunk_offset: 236); adding dummy dev data...\n",
      "  warnings.warn(msg)\n",
      "/Users/wjones/opt/anaconda3/envs/dsa/lib/python3.9/site-packages/fitdecode/reader.py:909: UserWarning: 'field \"native_field_num\" (idx #0) not found in message \"field_description\"' (local_mesg_num: 0; chunk_offset: 287); adding dummy dev data...\n",
      "  warnings.warn(msg)\n",
      "/Users/wjones/opt/anaconda3/envs/dsa/lib/python3.9/site-packages/fitdecode/reader.py:909: UserWarning: 'field \"native_field_num\" (idx #0) not found in message \"field_description\"' (local_mesg_num: 0; chunk_offset: 307); adding dummy dev data...\n",
      "  warnings.warn(msg)\n",
      "/Users/wjones/opt/anaconda3/envs/dsa/lib/python3.9/site-packages/fitdecode/reader.py:909: UserWarning: 'field \"native_field_num\" (idx #0) not found in message \"field_description\"' (local_mesg_num: 0; chunk_offset: 327); adding dummy dev data...\n",
      "  warnings.warn(msg)\n",
      "/Users/wjones/opt/anaconda3/envs/dsa/lib/python3.9/site-packages/fitdecode/reader.py:909: UserWarning: 'field \"native_field_num\" (idx #0) not found in message \"field_description\"' (local_mesg_num: 0; chunk_offset: 347); adding dummy dev data...\n",
      "  warnings.warn(msg)\n",
      "/Users/wjones/opt/anaconda3/envs/dsa/lib/python3.9/site-packages/fitdecode/reader.py:909: UserWarning: 'field \"native_field_num\" (idx #0) not found in message \"field_description\"' (local_mesg_num: 0; chunk_offset: 367); adding dummy dev data...\n",
      "  warnings.warn(msg)\n",
      "/Users/wjones/opt/anaconda3/envs/dsa/lib/python3.9/site-packages/fitdecode/reader.py:584: UserWarning: invalid field size 1 in definition message @ 23427 for type uint32 (expected a multiple of 4)\n",
      "  warnings.warn(msg)\n",
      "/Users/wjones/opt/anaconda3/envs/dsa/lib/python3.9/site-packages/fitdecode/reader.py:584: UserWarning: invalid field size 1 in definition message @ 64691 for type uint32 (expected a multiple of 4)\n",
      "  warnings.warn(msg)\n",
      "/Users/wjones/opt/anaconda3/envs/dsa/lib/python3.9/site-packages/fitdecode/reader.py:584: UserWarning: invalid field size 1 in definition message @ 70550 for type uint32 (expected a multiple of 4)\n",
      "  warnings.warn(msg)\n",
      "/Users/wjones/opt/anaconda3/envs/dsa/lib/python3.9/site-packages/fitdecode/reader.py:584: UserWarning: invalid field size 1 in definition message @ 86532 for type uint32 (expected a multiple of 4)\n",
      "  warnings.warn(msg)\n",
      "/Users/wjones/opt/anaconda3/envs/dsa/lib/python3.9/site-packages/fitdecode/reader.py:584: UserWarning: invalid field size 1 in definition message @ 150021 for type uint32 (expected a multiple of 4)\n",
      "  warnings.warn(msg)\n",
      "/Users/wjones/opt/anaconda3/envs/dsa/lib/python3.9/site-packages/fitdecode/reader.py:909: UserWarning: 'field \"native_field_num\" (idx #0) not found in message \"field_description\"' (local_mesg_num: 0; chunk_offset: 194); adding dummy dev data...\n",
      "  warnings.warn(msg)\n",
      "/Users/wjones/opt/anaconda3/envs/dsa/lib/python3.9/site-packages/fitdecode/reader.py:909: UserWarning: 'field \"native_field_num\" (idx #0) not found in message \"field_description\"' (local_mesg_num: 0; chunk_offset: 236); adding dummy dev data...\n",
      "  warnings.warn(msg)\n",
      "/Users/wjones/opt/anaconda3/envs/dsa/lib/python3.9/site-packages/fitdecode/reader.py:909: UserWarning: 'field \"native_field_num\" (idx #0) not found in message \"field_description\"' (local_mesg_num: 0; chunk_offset: 287); adding dummy dev data...\n",
      "  warnings.warn(msg)\n",
      "/Users/wjones/opt/anaconda3/envs/dsa/lib/python3.9/site-packages/fitdecode/reader.py:909: UserWarning: 'field \"native_field_num\" (idx #0) not found in message \"field_description\"' (local_mesg_num: 0; chunk_offset: 307); adding dummy dev data...\n",
      "  warnings.warn(msg)\n",
      "/Users/wjones/opt/anaconda3/envs/dsa/lib/python3.9/site-packages/fitdecode/reader.py:909: UserWarning: 'field \"native_field_num\" (idx #0) not found in message \"field_description\"' (local_mesg_num: 0; chunk_offset: 327); adding dummy dev data...\n",
      "  warnings.warn(msg)\n",
      "/Users/wjones/opt/anaconda3/envs/dsa/lib/python3.9/site-packages/fitdecode/reader.py:909: UserWarning: 'field \"native_field_num\" (idx #0) not found in message \"field_description\"' (local_mesg_num: 0; chunk_offset: 347); adding dummy dev data...\n",
      "  warnings.warn(msg)\n",
      "/Users/wjones/opt/anaconda3/envs/dsa/lib/python3.9/site-packages/fitdecode/reader.py:909: UserWarning: 'field \"native_field_num\" (idx #0) not found in message \"field_description\"' (local_mesg_num: 0; chunk_offset: 367); adding dummy dev data...\n",
      "  warnings.warn(msg)\n",
      "/Users/wjones/opt/anaconda3/envs/dsa/lib/python3.9/site-packages/fitdecode/reader.py:584: UserWarning: invalid field size 1 in definition message @ 638 for type uint32 (expected a multiple of 4)\n",
      "  warnings.warn(msg)\n",
      "/Users/wjones/opt/anaconda3/envs/dsa/lib/python3.9/site-packages/fitdecode/reader.py:584: UserWarning: invalid field size 1 in definition message @ 28142 for type uint32 (expected a multiple of 4)\n",
      "  warnings.warn(msg)\n",
      "/Users/wjones/opt/anaconda3/envs/dsa/lib/python3.9/site-packages/fitdecode/reader.py:584: UserWarning: invalid field size 1 in definition message @ 30108 for type uint32 (expected a multiple of 4)\n",
      "  warnings.warn(msg)\n",
      "/Users/wjones/opt/anaconda3/envs/dsa/lib/python3.9/site-packages/fitdecode/reader.py:584: UserWarning: invalid field size 1 in definition message @ 40513 for type uint32 (expected a multiple of 4)\n",
      "  warnings.warn(msg)\n",
      "/Users/wjones/opt/anaconda3/envs/dsa/lib/python3.9/site-packages/fitdecode/reader.py:584: UserWarning: invalid field size 1 in definition message @ 55342 for type uint32 (expected a multiple of 4)\n",
      "  warnings.warn(msg)\n",
      "/Users/wjones/opt/anaconda3/envs/dsa/lib/python3.9/site-packages/fitdecode/reader.py:909: UserWarning: 'field \"native_field_num\" (idx #0) not found in message \"field_description\"' (local_mesg_num: 0; chunk_offset: 194); adding dummy dev data...\n",
      "  warnings.warn(msg)\n",
      "/Users/wjones/opt/anaconda3/envs/dsa/lib/python3.9/site-packages/fitdecode/reader.py:909: UserWarning: 'field \"native_field_num\" (idx #0) not found in message \"field_description\"' (local_mesg_num: 0; chunk_offset: 236); adding dummy dev data...\n",
      "  warnings.warn(msg)\n",
      "/Users/wjones/opt/anaconda3/envs/dsa/lib/python3.9/site-packages/fitdecode/reader.py:909: UserWarning: 'field \"native_field_num\" (idx #0) not found in message \"field_description\"' (local_mesg_num: 0; chunk_offset: 287); adding dummy dev data...\n",
      "  warnings.warn(msg)\n",
      "/Users/wjones/opt/anaconda3/envs/dsa/lib/python3.9/site-packages/fitdecode/reader.py:909: UserWarning: 'field \"native_field_num\" (idx #0) not found in message \"field_description\"' (local_mesg_num: 0; chunk_offset: 307); adding dummy dev data...\n",
      "  warnings.warn(msg)\n",
      "/Users/wjones/opt/anaconda3/envs/dsa/lib/python3.9/site-packages/fitdecode/reader.py:909: UserWarning: 'field \"native_field_num\" (idx #0) not found in message \"field_description\"' (local_mesg_num: 0; chunk_offset: 327); adding dummy dev data...\n",
      "  warnings.warn(msg)\n",
      "/Users/wjones/opt/anaconda3/envs/dsa/lib/python3.9/site-packages/fitdecode/reader.py:909: UserWarning: 'field \"native_field_num\" (idx #0) not found in message \"field_description\"' (local_mesg_num: 0; chunk_offset: 347); adding dummy dev data...\n",
      "  warnings.warn(msg)\n",
      "/Users/wjones/opt/anaconda3/envs/dsa/lib/python3.9/site-packages/fitdecode/reader.py:909: UserWarning: 'field \"native_field_num\" (idx #0) not found in message \"field_description\"' (local_mesg_num: 0; chunk_offset: 367); adding dummy dev data...\n",
      "  warnings.warn(msg)\n",
      "/Users/wjones/opt/anaconda3/envs/dsa/lib/python3.9/site-packages/fitdecode/reader.py:584: UserWarning: invalid field size 1 in definition message @ 40656 for type uint32 (expected a multiple of 4)\n",
      "  warnings.warn(msg)\n",
      "/Users/wjones/opt/anaconda3/envs/dsa/lib/python3.9/site-packages/fitdecode/reader.py:584: UserWarning: invalid field size 1 in definition message @ 46786 for type uint32 (expected a multiple of 4)\n",
      "  warnings.warn(msg)\n",
      "/Users/wjones/opt/anaconda3/envs/dsa/lib/python3.9/site-packages/fitdecode/reader.py:909: UserWarning: 'field \"native_field_num\" (idx #0) not found in message \"field_description\"' (local_mesg_num: 0; chunk_offset: 194); adding dummy dev data...\n",
      "  warnings.warn(msg)\n",
      "/Users/wjones/opt/anaconda3/envs/dsa/lib/python3.9/site-packages/fitdecode/reader.py:909: UserWarning: 'field \"native_field_num\" (idx #0) not found in message \"field_description\"' (local_mesg_num: 0; chunk_offset: 236); adding dummy dev data...\n",
      "  warnings.warn(msg)\n",
      "/Users/wjones/opt/anaconda3/envs/dsa/lib/python3.9/site-packages/fitdecode/reader.py:909: UserWarning: 'field \"native_field_num\" (idx #0) not found in message \"field_description\"' (local_mesg_num: 0; chunk_offset: 287); adding dummy dev data...\n",
      "  warnings.warn(msg)\n",
      "/Users/wjones/opt/anaconda3/envs/dsa/lib/python3.9/site-packages/fitdecode/reader.py:909: UserWarning: 'field \"native_field_num\" (idx #0) not found in message \"field_description\"' (local_mesg_num: 0; chunk_offset: 307); adding dummy dev data...\n",
      "  warnings.warn(msg)\n",
      "/Users/wjones/opt/anaconda3/envs/dsa/lib/python3.9/site-packages/fitdecode/reader.py:909: UserWarning: 'field \"native_field_num\" (idx #0) not found in message \"field_description\"' (local_mesg_num: 0; chunk_offset: 327); adding dummy dev data...\n",
      "  warnings.warn(msg)\n",
      "/Users/wjones/opt/anaconda3/envs/dsa/lib/python3.9/site-packages/fitdecode/reader.py:909: UserWarning: 'field \"native_field_num\" (idx #0) not found in message \"field_description\"' (local_mesg_num: 0; chunk_offset: 347); adding dummy dev data...\n",
      "  warnings.warn(msg)\n",
      "/Users/wjones/opt/anaconda3/envs/dsa/lib/python3.9/site-packages/fitdecode/reader.py:909: UserWarning: 'field \"native_field_num\" (idx #0) not found in message \"field_description\"' (local_mesg_num: 0; chunk_offset: 367); adding dummy dev data...\n",
      "  warnings.warn(msg)\n",
      "/Users/wjones/opt/anaconda3/envs/dsa/lib/python3.9/site-packages/fitdecode/reader.py:584: UserWarning: invalid field size 1 in definition message @ 30541 for type uint32 (expected a multiple of 4)\n",
      "  warnings.warn(msg)\n",
      "/Users/wjones/opt/anaconda3/envs/dsa/lib/python3.9/site-packages/fitdecode/reader.py:584: UserWarning: invalid field size 1 in definition message @ 32121 for type uint32 (expected a multiple of 4)\n",
      "  warnings.warn(msg)\n",
      "/Users/wjones/opt/anaconda3/envs/dsa/lib/python3.9/site-packages/fitdecode/reader.py:909: UserWarning: 'field \"native_field_num\" (idx #0) not found in message \"field_description\"' (local_mesg_num: 0; chunk_offset: 200); adding dummy dev data...\n",
      "  warnings.warn(msg)\n",
      "/Users/wjones/opt/anaconda3/envs/dsa/lib/python3.9/site-packages/fitdecode/reader.py:909: UserWarning: 'field \"native_field_num\" (idx #0) not found in message \"field_description\"' (local_mesg_num: 0; chunk_offset: 242); adding dummy dev data...\n",
      "  warnings.warn(msg)\n",
      "/Users/wjones/opt/anaconda3/envs/dsa/lib/python3.9/site-packages/fitdecode/reader.py:909: UserWarning: 'field \"native_field_num\" (idx #0) not found in message \"field_description\"' (local_mesg_num: 0; chunk_offset: 293); adding dummy dev data...\n",
      "  warnings.warn(msg)\n",
      "/Users/wjones/opt/anaconda3/envs/dsa/lib/python3.9/site-packages/fitdecode/reader.py:909: UserWarning: 'field \"native_field_num\" (idx #0) not found in message \"field_description\"' (local_mesg_num: 0; chunk_offset: 313); adding dummy dev data...\n",
      "  warnings.warn(msg)\n",
      "/Users/wjones/opt/anaconda3/envs/dsa/lib/python3.9/site-packages/fitdecode/reader.py:909: UserWarning: 'field \"native_field_num\" (idx #0) not found in message \"field_description\"' (local_mesg_num: 0; chunk_offset: 333); adding dummy dev data...\n",
      "  warnings.warn(msg)\n",
      "/Users/wjones/opt/anaconda3/envs/dsa/lib/python3.9/site-packages/fitdecode/reader.py:909: UserWarning: 'field \"native_field_num\" (idx #0) not found in message \"field_description\"' (local_mesg_num: 0; chunk_offset: 353); adding dummy dev data...\n",
      "  warnings.warn(msg)\n",
      "/Users/wjones/opt/anaconda3/envs/dsa/lib/python3.9/site-packages/fitdecode/reader.py:909: UserWarning: 'field \"native_field_num\" (idx #0) not found in message \"field_description\"' (local_mesg_num: 0; chunk_offset: 373); adding dummy dev data...\n",
      "  warnings.warn(msg)\n",
      "/Users/wjones/opt/anaconda3/envs/dsa/lib/python3.9/site-packages/fitdecode/reader.py:909: UserWarning: 'field \"native_field_num\" (idx #0) not found in message \"field_description\"' (local_mesg_num: 0; chunk_offset: 119); adding dummy dev data...\n",
      "  warnings.warn(msg)\n",
      "/Users/wjones/opt/anaconda3/envs/dsa/lib/python3.9/site-packages/fitdecode/reader.py:909: UserWarning: 'field \"native_field_num\" (idx #0) not found in message \"field_description\"' (local_mesg_num: 0; chunk_offset: 194); adding dummy dev data...\n",
      "  warnings.warn(msg)\n",
      "/Users/wjones/opt/anaconda3/envs/dsa/lib/python3.9/site-packages/fitdecode/reader.py:909: UserWarning: 'field \"native_field_num\" (idx #0) not found in message \"field_description\"' (local_mesg_num: 0; chunk_offset: 236); adding dummy dev data...\n",
      "  warnings.warn(msg)\n",
      "/Users/wjones/opt/anaconda3/envs/dsa/lib/python3.9/site-packages/fitdecode/reader.py:909: UserWarning: 'field \"native_field_num\" (idx #0) not found in message \"field_description\"' (local_mesg_num: 0; chunk_offset: 287); adding dummy dev data...\n",
      "  warnings.warn(msg)\n",
      "/Users/wjones/opt/anaconda3/envs/dsa/lib/python3.9/site-packages/fitdecode/reader.py:909: UserWarning: 'field \"native_field_num\" (idx #0) not found in message \"field_description\"' (local_mesg_num: 0; chunk_offset: 307); adding dummy dev data...\n",
      "  warnings.warn(msg)\n",
      "/Users/wjones/opt/anaconda3/envs/dsa/lib/python3.9/site-packages/fitdecode/reader.py:909: UserWarning: 'field \"native_field_num\" (idx #0) not found in message \"field_description\"' (local_mesg_num: 0; chunk_offset: 327); adding dummy dev data...\n",
      "  warnings.warn(msg)\n",
      "/Users/wjones/opt/anaconda3/envs/dsa/lib/python3.9/site-packages/fitdecode/reader.py:909: UserWarning: 'field \"native_field_num\" (idx #0) not found in message \"field_description\"' (local_mesg_num: 0; chunk_offset: 347); adding dummy dev data...\n",
      "  warnings.warn(msg)\n",
      "/Users/wjones/opt/anaconda3/envs/dsa/lib/python3.9/site-packages/fitdecode/reader.py:909: UserWarning: 'field \"native_field_num\" (idx #0) not found in message \"field_description\"' (local_mesg_num: 0; chunk_offset: 367); adding dummy dev data...\n",
      "  warnings.warn(msg)\n",
      "/Users/wjones/opt/anaconda3/envs/dsa/lib/python3.9/site-packages/fitdecode/reader.py:584: UserWarning: invalid field size 1 in definition message @ 134656 for type uint32 (expected a multiple of 4)\n",
      "  warnings.warn(msg)\n",
      "/Users/wjones/opt/anaconda3/envs/dsa/lib/python3.9/site-packages/fitdecode/reader.py:909: UserWarning: 'field \"native_field_num\" (idx #0) not found in message \"field_description\"' (local_mesg_num: 0; chunk_offset: 194); adding dummy dev data...\n",
      "  warnings.warn(msg)\n",
      "/Users/wjones/opt/anaconda3/envs/dsa/lib/python3.9/site-packages/fitdecode/reader.py:909: UserWarning: 'field \"native_field_num\" (idx #0) not found in message \"field_description\"' (local_mesg_num: 0; chunk_offset: 236); adding dummy dev data...\n",
      "  warnings.warn(msg)\n",
      "/Users/wjones/opt/anaconda3/envs/dsa/lib/python3.9/site-packages/fitdecode/reader.py:909: UserWarning: 'field \"native_field_num\" (idx #0) not found in message \"field_description\"' (local_mesg_num: 0; chunk_offset: 287); adding dummy dev data...\n",
      "  warnings.warn(msg)\n",
      "/Users/wjones/opt/anaconda3/envs/dsa/lib/python3.9/site-packages/fitdecode/reader.py:909: UserWarning: 'field \"native_field_num\" (idx #0) not found in message \"field_description\"' (local_mesg_num: 0; chunk_offset: 307); adding dummy dev data...\n",
      "  warnings.warn(msg)\n",
      "/Users/wjones/opt/anaconda3/envs/dsa/lib/python3.9/site-packages/fitdecode/reader.py:909: UserWarning: 'field \"native_field_num\" (idx #0) not found in message \"field_description\"' (local_mesg_num: 0; chunk_offset: 327); adding dummy dev data...\n",
      "  warnings.warn(msg)\n",
      "/Users/wjones/opt/anaconda3/envs/dsa/lib/python3.9/site-packages/fitdecode/reader.py:909: UserWarning: 'field \"native_field_num\" (idx #0) not found in message \"field_description\"' (local_mesg_num: 0; chunk_offset: 347); adding dummy dev data...\n",
      "  warnings.warn(msg)\n",
      "/Users/wjones/opt/anaconda3/envs/dsa/lib/python3.9/site-packages/fitdecode/reader.py:909: UserWarning: 'field \"native_field_num\" (idx #0) not found in message \"field_description\"' (local_mesg_num: 0; chunk_offset: 367); adding dummy dev data...\n",
      "  warnings.warn(msg)\n",
      "/Users/wjones/opt/anaconda3/envs/dsa/lib/python3.9/site-packages/fitdecode/reader.py:584: UserWarning: invalid field size 1 in definition message @ 45076 for type uint32 (expected a multiple of 4)\n",
      "  warnings.warn(msg)\n",
      "/Users/wjones/opt/anaconda3/envs/dsa/lib/python3.9/site-packages/fitdecode/reader.py:584: UserWarning: invalid field size 1 in definition message @ 74178 for type uint32 (expected a multiple of 4)\n",
      "  warnings.warn(msg)\n",
      "/Users/wjones/opt/anaconda3/envs/dsa/lib/python3.9/site-packages/fitdecode/reader.py:584: UserWarning: invalid field size 1 in definition message @ 100122 for type uint32 (expected a multiple of 4)\n",
      "  warnings.warn(msg)\n",
      "/Users/wjones/opt/anaconda3/envs/dsa/lib/python3.9/site-packages/fitdecode/reader.py:584: UserWarning: invalid field size 1 in definition message @ 139764 for type uint32 (expected a multiple of 4)\n",
      "  warnings.warn(msg)\n",
      "/Users/wjones/opt/anaconda3/envs/dsa/lib/python3.9/site-packages/fitdecode/reader.py:584: UserWarning: invalid field size 1 in definition message @ 166847 for type uint32 (expected a multiple of 4)\n",
      "  warnings.warn(msg)\n",
      "/Users/wjones/opt/anaconda3/envs/dsa/lib/python3.9/site-packages/fitdecode/reader.py:584: UserWarning: invalid field size 1 in definition message @ 236691 for type uint32 (expected a multiple of 4)\n",
      "  warnings.warn(msg)\n",
      "/Users/wjones/opt/anaconda3/envs/dsa/lib/python3.9/site-packages/fitdecode/reader.py:584: UserWarning: invalid field size 1 in definition message @ 246643 for type uint32 (expected a multiple of 4)\n",
      "  warnings.warn(msg)\n",
      "/Users/wjones/opt/anaconda3/envs/dsa/lib/python3.9/site-packages/fitdecode/reader.py:909: UserWarning: 'field \"native_field_num\" (idx #0) not found in message \"field_description\"' (local_mesg_num: 0; chunk_offset: 194); adding dummy dev data...\n",
      "  warnings.warn(msg)\n",
      "/Users/wjones/opt/anaconda3/envs/dsa/lib/python3.9/site-packages/fitdecode/reader.py:909: UserWarning: 'field \"native_field_num\" (idx #0) not found in message \"field_description\"' (local_mesg_num: 0; chunk_offset: 236); adding dummy dev data...\n",
      "  warnings.warn(msg)\n",
      "/Users/wjones/opt/anaconda3/envs/dsa/lib/python3.9/site-packages/fitdecode/reader.py:909: UserWarning: 'field \"native_field_num\" (idx #0) not found in message \"field_description\"' (local_mesg_num: 0; chunk_offset: 287); adding dummy dev data...\n",
      "  warnings.warn(msg)\n",
      "/Users/wjones/opt/anaconda3/envs/dsa/lib/python3.9/site-packages/fitdecode/reader.py:909: UserWarning: 'field \"native_field_num\" (idx #0) not found in message \"field_description\"' (local_mesg_num: 0; chunk_offset: 307); adding dummy dev data...\n",
      "  warnings.warn(msg)\n",
      "/Users/wjones/opt/anaconda3/envs/dsa/lib/python3.9/site-packages/fitdecode/reader.py:909: UserWarning: 'field \"native_field_num\" (idx #0) not found in message \"field_description\"' (local_mesg_num: 0; chunk_offset: 327); adding dummy dev data...\n",
      "  warnings.warn(msg)\n",
      "/Users/wjones/opt/anaconda3/envs/dsa/lib/python3.9/site-packages/fitdecode/reader.py:909: UserWarning: 'field \"native_field_num\" (idx #0) not found in message \"field_description\"' (local_mesg_num: 0; chunk_offset: 347); adding dummy dev data...\n",
      "  warnings.warn(msg)\n",
      "/Users/wjones/opt/anaconda3/envs/dsa/lib/python3.9/site-packages/fitdecode/reader.py:909: UserWarning: 'field \"native_field_num\" (idx #0) not found in message \"field_description\"' (local_mesg_num: 0; chunk_offset: 367); adding dummy dev data...\n",
      "  warnings.warn(msg)\n",
      "/Users/wjones/opt/anaconda3/envs/dsa/lib/python3.9/site-packages/fitdecode/reader.py:584: UserWarning: invalid field size 1 in definition message @ 27078 for type uint32 (expected a multiple of 4)\n",
      "  warnings.warn(msg)\n",
      "/Users/wjones/opt/anaconda3/envs/dsa/lib/python3.9/site-packages/fitdecode/reader.py:584: UserWarning: invalid field size 1 in definition message @ 60563 for type uint32 (expected a multiple of 4)\n",
      "  warnings.warn(msg)\n",
      "/Users/wjones/opt/anaconda3/envs/dsa/lib/python3.9/site-packages/fitdecode/reader.py:584: UserWarning: invalid field size 1 in definition message @ 61317 for type uint32 (expected a multiple of 4)\n",
      "  warnings.warn(msg)\n",
      "/Users/wjones/opt/anaconda3/envs/dsa/lib/python3.9/site-packages/fitdecode/reader.py:584: UserWarning: invalid field size 1 in definition message @ 65672 for type uint32 (expected a multiple of 4)\n",
      "  warnings.warn(msg)\n",
      "/Users/wjones/opt/anaconda3/envs/dsa/lib/python3.9/site-packages/fitdecode/reader.py:909: UserWarning: 'field \"native_field_num\" (idx #0) not found in message \"field_description\"' (local_mesg_num: 0; chunk_offset: 194); adding dummy dev data...\n",
      "  warnings.warn(msg)\n",
      "/Users/wjones/opt/anaconda3/envs/dsa/lib/python3.9/site-packages/fitdecode/reader.py:909: UserWarning: 'field \"native_field_num\" (idx #0) not found in message \"field_description\"' (local_mesg_num: 0; chunk_offset: 236); adding dummy dev data...\n",
      "  warnings.warn(msg)\n",
      "/Users/wjones/opt/anaconda3/envs/dsa/lib/python3.9/site-packages/fitdecode/reader.py:909: UserWarning: 'field \"native_field_num\" (idx #0) not found in message \"field_description\"' (local_mesg_num: 0; chunk_offset: 287); adding dummy dev data...\n",
      "  warnings.warn(msg)\n",
      "/Users/wjones/opt/anaconda3/envs/dsa/lib/python3.9/site-packages/fitdecode/reader.py:909: UserWarning: 'field \"native_field_num\" (idx #0) not found in message \"field_description\"' (local_mesg_num: 0; chunk_offset: 307); adding dummy dev data...\n",
      "  warnings.warn(msg)\n",
      "/Users/wjones/opt/anaconda3/envs/dsa/lib/python3.9/site-packages/fitdecode/reader.py:909: UserWarning: 'field \"native_field_num\" (idx #0) not found in message \"field_description\"' (local_mesg_num: 0; chunk_offset: 327); adding dummy dev data...\n",
      "  warnings.warn(msg)\n",
      "/Users/wjones/opt/anaconda3/envs/dsa/lib/python3.9/site-packages/fitdecode/reader.py:909: UserWarning: 'field \"native_field_num\" (idx #0) not found in message \"field_description\"' (local_mesg_num: 0; chunk_offset: 347); adding dummy dev data...\n",
      "  warnings.warn(msg)\n",
      "/Users/wjones/opt/anaconda3/envs/dsa/lib/python3.9/site-packages/fitdecode/reader.py:909: UserWarning: 'field \"native_field_num\" (idx #0) not found in message \"field_description\"' (local_mesg_num: 0; chunk_offset: 367); adding dummy dev data...\n",
      "  warnings.warn(msg)\n",
      "/Users/wjones/opt/anaconda3/envs/dsa/lib/python3.9/site-packages/fitdecode/reader.py:584: UserWarning: invalid field size 1 in definition message @ 27078 for type uint32 (expected a multiple of 4)\n",
      "  warnings.warn(msg)\n",
      "/Users/wjones/opt/anaconda3/envs/dsa/lib/python3.9/site-packages/fitdecode/reader.py:584: UserWarning: invalid field size 1 in definition message @ 54981 for type uint32 (expected a multiple of 4)\n",
      "  warnings.warn(msg)\n",
      "/Users/wjones/opt/anaconda3/envs/dsa/lib/python3.9/site-packages/fitdecode/reader.py:584: UserWarning: invalid field size 1 in definition message @ 55754 for type uint32 (expected a multiple of 4)\n",
      "  warnings.warn(msg)\n",
      "/Users/wjones/opt/anaconda3/envs/dsa/lib/python3.9/site-packages/fitdecode/reader.py:584: UserWarning: invalid field size 1 in definition message @ 57999 for type uint32 (expected a multiple of 4)\n",
      "  warnings.warn(msg)\n",
      "/Users/wjones/opt/anaconda3/envs/dsa/lib/python3.9/site-packages/fitdecode/reader.py:584: UserWarning: invalid field size 1 in definition message @ 66184 for type uint32 (expected a multiple of 4)\n",
      "  warnings.warn(msg)\n",
      "/Users/wjones/opt/anaconda3/envs/dsa/lib/python3.9/site-packages/fitdecode/reader.py:584: UserWarning: invalid field size 1 in definition message @ 68738 for type uint32 (expected a multiple of 4)\n",
      "  warnings.warn(msg)\n",
      "/Users/wjones/opt/anaconda3/envs/dsa/lib/python3.9/site-packages/fitdecode/reader.py:584: UserWarning: invalid field size 1 in definition message @ 69488 for type uint32 (expected a multiple of 4)\n",
      "  warnings.warn(msg)\n",
      "/Users/wjones/opt/anaconda3/envs/dsa/lib/python3.9/site-packages/fitdecode/reader.py:584: UserWarning: invalid field size 1 in definition message @ 70514 for type uint32 (expected a multiple of 4)\n",
      "  warnings.warn(msg)\n",
      "/Users/wjones/opt/anaconda3/envs/dsa/lib/python3.9/site-packages/fitdecode/reader.py:584: UserWarning: invalid field size 1 in definition message @ 71051 for type uint32 (expected a multiple of 4)\n",
      "  warnings.warn(msg)\n",
      "/Users/wjones/opt/anaconda3/envs/dsa/lib/python3.9/site-packages/fitdecode/reader.py:584: UserWarning: invalid field size 1 in definition message @ 71854 for type uint32 (expected a multiple of 4)\n",
      "  warnings.warn(msg)\n",
      "/Users/wjones/opt/anaconda3/envs/dsa/lib/python3.9/site-packages/fitdecode/reader.py:584: UserWarning: invalid field size 1 in definition message @ 73329 for type uint32 (expected a multiple of 4)\n",
      "  warnings.warn(msg)\n",
      "/Users/wjones/opt/anaconda3/envs/dsa/lib/python3.9/site-packages/fitdecode/reader.py:584: UserWarning: invalid field size 1 in definition message @ 81834 for type uint32 (expected a multiple of 4)\n",
      "  warnings.warn(msg)\n",
      "/Users/wjones/opt/anaconda3/envs/dsa/lib/python3.9/site-packages/fitdecode/reader.py:584: UserWarning: invalid field size 1 in definition message @ 84523 for type uint32 (expected a multiple of 4)\n",
      "  warnings.warn(msg)\n",
      "/Users/wjones/opt/anaconda3/envs/dsa/lib/python3.9/site-packages/fitdecode/reader.py:584: UserWarning: invalid field size 1 in definition message @ 100012 for type uint32 (expected a multiple of 4)\n",
      "  warnings.warn(msg)\n",
      "/Users/wjones/opt/anaconda3/envs/dsa/lib/python3.9/site-packages/fitdecode/reader.py:584: UserWarning: invalid field size 1 in definition message @ 108077 for type uint32 (expected a multiple of 4)\n",
      "  warnings.warn(msg)\n",
      "/Users/wjones/opt/anaconda3/envs/dsa/lib/python3.9/site-packages/fitdecode/reader.py:584: UserWarning: invalid field size 1 in definition message @ 108710 for type uint32 (expected a multiple of 4)\n",
      "  warnings.warn(msg)\n",
      "/Users/wjones/opt/anaconda3/envs/dsa/lib/python3.9/site-packages/fitdecode/reader.py:909: UserWarning: 'field \"native_field_num\" (idx #0) not found in message \"field_description\"' (local_mesg_num: 0; chunk_offset: 194); adding dummy dev data...\n",
      "  warnings.warn(msg)\n",
      "/Users/wjones/opt/anaconda3/envs/dsa/lib/python3.9/site-packages/fitdecode/reader.py:909: UserWarning: 'field \"native_field_num\" (idx #0) not found in message \"field_description\"' (local_mesg_num: 0; chunk_offset: 236); adding dummy dev data...\n",
      "  warnings.warn(msg)\n",
      "/Users/wjones/opt/anaconda3/envs/dsa/lib/python3.9/site-packages/fitdecode/reader.py:909: UserWarning: 'field \"native_field_num\" (idx #0) not found in message \"field_description\"' (local_mesg_num: 0; chunk_offset: 287); adding dummy dev data...\n",
      "  warnings.warn(msg)\n",
      "/Users/wjones/opt/anaconda3/envs/dsa/lib/python3.9/site-packages/fitdecode/reader.py:909: UserWarning: 'field \"native_field_num\" (idx #0) not found in message \"field_description\"' (local_mesg_num: 0; chunk_offset: 307); adding dummy dev data...\n",
      "  warnings.warn(msg)\n",
      "/Users/wjones/opt/anaconda3/envs/dsa/lib/python3.9/site-packages/fitdecode/reader.py:909: UserWarning: 'field \"native_field_num\" (idx #0) not found in message \"field_description\"' (local_mesg_num: 0; chunk_offset: 327); adding dummy dev data...\n",
      "  warnings.warn(msg)\n",
      "/Users/wjones/opt/anaconda3/envs/dsa/lib/python3.9/site-packages/fitdecode/reader.py:909: UserWarning: 'field \"native_field_num\" (idx #0) not found in message \"field_description\"' (local_mesg_num: 0; chunk_offset: 347); adding dummy dev data...\n",
      "  warnings.warn(msg)\n",
      "/Users/wjones/opt/anaconda3/envs/dsa/lib/python3.9/site-packages/fitdecode/reader.py:909: UserWarning: 'field \"native_field_num\" (idx #0) not found in message \"field_description\"' (local_mesg_num: 0; chunk_offset: 367); adding dummy dev data...\n",
      "  warnings.warn(msg)\n",
      "/Users/wjones/opt/anaconda3/envs/dsa/lib/python3.9/site-packages/fitdecode/reader.py:584: UserWarning: invalid field size 1 in definition message @ 27857 for type uint32 (expected a multiple of 4)\n",
      "  warnings.warn(msg)\n",
      "/Users/wjones/opt/anaconda3/envs/dsa/lib/python3.9/site-packages/fitdecode/reader.py:584: UserWarning: invalid field size 1 in definition message @ 52184 for type uint32 (expected a multiple of 4)\n",
      "  warnings.warn(msg)\n",
      "/Users/wjones/opt/anaconda3/envs/dsa/lib/python3.9/site-packages/fitdecode/reader.py:584: UserWarning: invalid field size 1 in definition message @ 52886 for type uint32 (expected a multiple of 4)\n",
      "  warnings.warn(msg)\n",
      "/Users/wjones/opt/anaconda3/envs/dsa/lib/python3.9/site-packages/fitdecode/reader.py:584: UserWarning: invalid field size 1 in definition message @ 53531 for type uint32 (expected a multiple of 4)\n",
      "  warnings.warn(msg)\n",
      "/Users/wjones/opt/anaconda3/envs/dsa/lib/python3.9/site-packages/fitdecode/reader.py:584: UserWarning: invalid field size 1 in definition message @ 53715 for type uint32 (expected a multiple of 4)\n",
      "  warnings.warn(msg)\n",
      "/Users/wjones/opt/anaconda3/envs/dsa/lib/python3.9/site-packages/fitdecode/reader.py:584: UserWarning: invalid field size 1 in definition message @ 58802 for type uint32 (expected a multiple of 4)\n",
      "  warnings.warn(msg)\n",
      "/Users/wjones/opt/anaconda3/envs/dsa/lib/python3.9/site-packages/fitdecode/reader.py:584: UserWarning: invalid field size 1 in definition message @ 94644 for type uint32 (expected a multiple of 4)\n",
      "  warnings.warn(msg)\n",
      "/Users/wjones/opt/anaconda3/envs/dsa/lib/python3.9/site-packages/fitdecode/reader.py:584: UserWarning: invalid field size 1 in definition message @ 120272 for type uint32 (expected a multiple of 4)\n",
      "  warnings.warn(msg)\n",
      "/Users/wjones/opt/anaconda3/envs/dsa/lib/python3.9/site-packages/fitdecode/reader.py:584: UserWarning: invalid field size 1 in definition message @ 120782 for type uint32 (expected a multiple of 4)\n",
      "  warnings.warn(msg)\n",
      "/Users/wjones/opt/anaconda3/envs/dsa/lib/python3.9/site-packages/fitdecode/reader.py:584: UserWarning: invalid field size 1 in definition message @ 142060 for type uint32 (expected a multiple of 4)\n",
      "  warnings.warn(msg)\n",
      "/Users/wjones/opt/anaconda3/envs/dsa/lib/python3.9/site-packages/fitdecode/reader.py:584: UserWarning: invalid field size 1 in definition message @ 157998 for type uint32 (expected a multiple of 4)\n",
      "  warnings.warn(msg)\n"
     ]
    }
   ],
   "source": [
    "#fit_to_gpx('data/james_activities')"
   ]
  },
  {
   "cell_type": "code",
   "execution_count": 253,
   "metadata": {},
   "outputs": [],
   "source": [
    "def compare_user_activities_to_segment(segment):\n",
    "    pass"
   ]
  },
  {
   "cell_type": "code",
   "execution_count": 267,
   "metadata": {},
   "outputs": [
    {
     "name": "stdout",
     "output_type": "stream",
     "text": [
      "Requirement already satisfied: dtaidistance in /Users/wjones/opt/anaconda3/envs/dsa/lib/python3.9/site-packages (2.3.10)\n",
      "Requirement already satisfied: numpy in /Users/wjones/opt/anaconda3/envs/dsa/lib/python3.9/site-packages (from dtaidistance) (1.23.4)\n"
     ]
    }
   ],
   "source": [
    "!pip install dtaidistance\n",
    "from dtaidistance import dtw\n",
    "from dtaidistance import dtw_visualisation as dtwvis"
   ]
  },
  {
   "cell_type": "code",
   "execution_count": 260,
   "metadata": {},
   "outputs": [
    {
     "name": "stdout",
     "output_type": "stream",
     "text": [
      "1596\n",
      "125\n"
     ]
    },
    {
     "data": {
      "text/plain": [
       "(None, None)"
      ]
     },
     "execution_count": 260,
     "metadata": {},
     "output_type": "execute_result"
    }
   ],
   "source": [
    "l = graphing(arr[1], claremont_turkey_trot)\n",
    "print(len(l[0]))\n",
    "print(len(l[1]))\n",
    "path = dtw.warping_path(l[0], l[1])\n",
    "dtwvis.plot_warping(l[0], l[1], path, filename=\"warp.png\")"
   ]
  },
  {
   "cell_type": "code",
   "execution_count": 268,
   "metadata": {},
   "outputs": [
    {
     "name": "stderr",
     "output_type": "stream",
     "text": [
      "The compiled dtaidistance C library is not available.\n",
      "See the documentation for alternative installation options.\n"
     ]
    },
    {
     "ename": "Exception",
     "evalue": "The compiled dtaidistance C library is not available.\nSee the documentation for alternative installation options.",
     "output_type": "error",
     "traceback": [
      "\u001b[0;31m---------------------------------------------------------------------------\u001b[0m",
      "\u001b[0;31mException\u001b[0m                                 Traceback (most recent call last)",
      "Cell \u001b[0;32mIn[268], line 1\u001b[0m\n\u001b[0;32m----> 1\u001b[0m d \u001b[39m=\u001b[39m dtw\u001b[39m.\u001b[39;49mdistance_fast(l[\u001b[39m0\u001b[39;49m], l[\u001b[39m1\u001b[39;49m], use_pruning\u001b[39m=\u001b[39;49m\u001b[39mTrue\u001b[39;49;00m)\n\u001b[1;32m      2\u001b[0m \u001b[39mprint\u001b[39m(d)\n",
      "File \u001b[0;32m~/opt/anaconda3/envs/dsa/lib/python3.9/site-packages/dtaidistance/dtw.py:335\u001b[0m, in \u001b[0;36mdistance_fast\u001b[0;34m(s1, s2, window, max_dist, max_step, max_length_diff, penalty, psi, use_pruning, only_ub)\u001b[0m\n\u001b[1;32m    326\u001b[0m \u001b[39mdef\u001b[39;00m \u001b[39mdistance_fast\u001b[39m(s1, s2, window\u001b[39m=\u001b[39m\u001b[39mNone\u001b[39;00m, max_dist\u001b[39m=\u001b[39m\u001b[39mNone\u001b[39;00m,\n\u001b[1;32m    327\u001b[0m                   max_step\u001b[39m=\u001b[39m\u001b[39mNone\u001b[39;00m, max_length_diff\u001b[39m=\u001b[39m\u001b[39mNone\u001b[39;00m, penalty\u001b[39m=\u001b[39m\u001b[39mNone\u001b[39;00m, psi\u001b[39m=\u001b[39m\u001b[39mNone\u001b[39;00m, use_pruning\u001b[39m=\u001b[39m\u001b[39mFalse\u001b[39;00m, only_ub\u001b[39m=\u001b[39m\u001b[39mFalse\u001b[39;00m):\n\u001b[1;32m    328\u001b[0m     \u001b[39m\"\"\"Same as :meth:`distance` but with different defaults to chose the fast C-based version of\u001b[39;00m\n\u001b[1;32m    329\u001b[0m \u001b[39m    the implementation (use_c = True).\u001b[39;00m\n\u001b[1;32m    330\u001b[0m \n\u001b[0;32m   (...)\u001b[0m\n\u001b[1;32m    333\u001b[0m \u001b[39m    ``array.array('d', [1,2,3])``\u001b[39;00m\n\u001b[1;32m    334\u001b[0m \u001b[39m    \"\"\"\u001b[39;00m\n\u001b[0;32m--> 335\u001b[0m     _check_library(raise_exception\u001b[39m=\u001b[39;49m\u001b[39mTrue\u001b[39;49;00m)\n\u001b[1;32m    336\u001b[0m     \u001b[39m# Check that Numpy arrays for C contiguous\u001b[39;00m\n\u001b[1;32m    337\u001b[0m     s1 \u001b[39m=\u001b[39m util_numpy\u001b[39m.\u001b[39mverify_np_array(s1)\n",
      "File \u001b[0;32m~/opt/anaconda3/envs/dsa/lib/python3.9/site-packages/dtaidistance/dtw.py:94\u001b[0m, in \u001b[0;36m_check_library\u001b[0;34m(include_omp, raise_exception)\u001b[0m\n\u001b[1;32m     92\u001b[0m     logger\u001b[39m.\u001b[39merror(msg)\n\u001b[1;32m     93\u001b[0m     \u001b[39mif\u001b[39;00m raise_exception:\n\u001b[0;32m---> 94\u001b[0m         \u001b[39mraise\u001b[39;00m \u001b[39mException\u001b[39;00m(msg)\n\u001b[1;32m     95\u001b[0m \u001b[39mif\u001b[39;00m include_omp \u001b[39mand\u001b[39;00m (dtw_cc_omp \u001b[39mis\u001b[39;00m \u001b[39mNone\u001b[39;00m \u001b[39mor\u001b[39;00m \u001b[39mnot\u001b[39;00m dtw_cc_omp\u001b[39m.\u001b[39mis_openmp_supported()):\n\u001b[1;32m     96\u001b[0m     msg \u001b[39m=\u001b[39m \u001b[39m\"\u001b[39m\u001b[39mThe compiled dtaidistance C-OMP library \u001b[39m\u001b[39m\"\u001b[39m\n",
      "\u001b[0;31mException\u001b[0m: The compiled dtaidistance C library is not available.\nSee the documentation for alternative installation options."
     ]
    }
   ],
   "source": [
    "d = dtw.distance_fast(l[0], l[1], use_pruning=True)\n",
    "print(d)"
   ]
  },
  {
   "cell_type": "code",
   "execution_count": 269,
   "metadata": {},
   "outputs": [
    {
     "name": "stdout",
     "output_type": "stream",
     "text": [
      "Cannot import OMP-based library (dtw_cc_omp)\n",
      "Cannot import Numpy-based library (dtw_cc_numpy)\n",
      "\n",
      "Not all libraries are available in your installation. \n",
      "You can rerun the compilation from source or pip install in verbose mode:\n",
      "pip install -vvv --upgrade --force-reinstall --no-deps --no-binary dtaidistance dtaidistance\n",
      "In case you need to use an older version of numpy, compile against your current installation:\n",
      "pip install -vvv --upgrade --force-reinstall --no-deps --no-build-isolation --no-binary dtaidistance dtaidistance\n",
      "\n",
      "Share the following information when submitting a bug report:\n",
      "== Packages ==\n",
      "- Cannot import OMP-based library (dtw_cc_omp)\n",
      "- dlopen(/Users/wjones/opt/anaconda3/envs/dsa/lib/python3.9/site-packages/dtaidistance/dtw_cc_omp.cpython-39-darwin.so, 0x0002): Library not loaded: /usr/local/lib/libomp.dylib\n",
      "  Referenced from: <FD5B81E3-F92A-3645-8432-9E0A64CE90AC> /Users/wjones/opt/anaconda3/envs/dsa/lib/python3.9/site-packages/dtaidistance/dtw_cc_omp.cpython-39-darwin.so\n",
      "  Reason: tried: '/usr/local/lib/libomp.dylib' (no such file), '/System/Volumes/Preboot/Cryptexes/OS/usr/local/lib/libomp.dylib' (no such file), '/usr/local/lib/libomp.dylib' (no such file), '/usr/lib/libomp.dylib' (no such file, not in dyld cache)\n",
      "- Cannot import Numpy-based library (dtw_cc_numpy)\n",
      "- dlopen(/Users/wjones/opt/anaconda3/envs/dsa/lib/python3.9/site-packages/dtaidistance/dtw_cc_numpy.cpython-39-darwin.so, 0x0002): Library not loaded: /usr/local/lib/libomp.dylib\n",
      "  Referenced from: <D0FDC692-B8D4-323C-B19D-B3776BD800AD> /Users/wjones/opt/anaconda3/envs/dsa/lib/python3.9/site-packages/dtaidistance/dtw_cc_numpy.cpython-39-darwin.so\n",
      "  Reason: tried: '/usr/local/lib/libomp.dylib' (no such file), '/System/Volumes/Preboot/Cryptexes/OS/usr/local/lib/libomp.dylib' (no such file), '/usr/local/lib/libomp.dylib' (no such file), '/usr/lib/libomp.dylib' (no such file, not in dyld cache)\n",
      "- Numpy version: 1.23.4\n",
      "- Matplotlib version: 3.5.1\n",
      "- Scipy version: 1.9.3\n",
      "== System information ==\n",
      "namespace(name='cpython', cache_tag='cpython-39', version=sys.version_info(major=3, minor=9, micro=15, releaselevel='final', serial=0), hexversion=50925552, _multiarch='darwin')\n",
      "== Compilation information ==\n",
      "Compiler type: unix\n",
      "--noopenmp: 0\n",
      "--forceopenmp: 0\n",
      "--noxpreprocessor: 0\n",
      "--forcellvm: 0\n",
      "--forcegnugcc: 0\n",
      "--forcestatic: 0\n",
      "Cython found (during compilation)\n",
      "- Version: 0.29.32\n",
      "- Locations: <module 'Cython' from '/private/var/folders/24/8k48jl6d249_n_qfxwsl6xvm0000gn/T/build-env-redq7n78/lib/python3.9/site-packages/Cython/__init__.py'>\n",
      "Numpy found (during compilation):\n",
      "- Version: 1.23.3\n",
      "- Location: <module 'numpy' from '/private/var/folders/24/8k48jl6d249_n_qfxwsl6xvm0000gn/T/build-env-redq7n78/lib/python3.9/site-packages/numpy/__init__.py'>\n",
      "Checking if gcc redirects to clang\n",
      "gcc --version # with stdout=-1, stderr=-1, input=, encoding=ascii\n",
      "\n",
      "Apple clang version 14.0.0 (clang-1400.0.29.102)\n",
      "... found clang\n",
      "Using LLVM settings (gcc)\n",
      "Checking for OpenMP availability for gcc\n",
      "gcc -dM -E -Xpreprocessor -fopenmp - # with stdout=-1, stderr=-1, input=, encoding=ascii\n",
      "\n",
      "#define _OPENMP 201811\n",
      "... found OpenMP\n",
      "All extensions:\n",
      "[<setuptools.extension.Extension('dtaidistance.dtw_cc') at 0x10dcd0610>, <setuptools.extension.Extension('dtaidistance.ed_cc') at 0x10dcd0b20>, <setuptools.extension.Extension('dtaidistance.dtw_cc_omp') at 0x10dcd0fa0>, <setuptools.extension.Extension('dtaidistance.dtw_cc_numpy') at 0x10dccf9a0>]\n",
      "\n",
      "\n",
      "==\n"
     ]
    },
    {
     "data": {
      "text/plain": [
       "False"
      ]
     },
     "execution_count": 269,
     "metadata": {},
     "output_type": "execute_result"
    }
   ],
   "source": [
    "dtw.try_import_c(verbose=True)"
   ]
  },
  {
   "cell_type": "code",
   "execution_count": null,
   "metadata": {},
   "outputs": [],
   "source": []
  }
 ],
 "metadata": {
  "kernelspec": {
   "display_name": "dsa",
   "language": "python",
   "name": "python3"
  },
  "language_info": {
   "codemirror_mode": {
    "name": "ipython",
    "version": 3
   },
   "file_extension": ".py",
   "mimetype": "text/x-python",
   "name": "python",
   "nbconvert_exporter": "python",
   "pygments_lexer": "ipython3",
   "version": "3.9.15"
  },
  "orig_nbformat": 4,
  "vscode": {
   "interpreter": {
    "hash": "60a029060c274fe779a2fcc7bb51dacc2ea85f5b99cbc3686fa63f7965c9aff9"
   }
  }
 },
 "nbformat": 4,
 "nbformat_minor": 2
}
